2024-11-19 15:20:26,931 - INFO - Starting parallel processing with 1 processes
2024-11-19 15:20:36,047 - INFO - Starting processing of file: u00024s00001_hw00004.svc
2024-11-19 15:20:37,704 - WARNING - From c:\Github\Thesis-Project\timegan\main.py:20: The name tf.disable_eager_execution is deprecated. Please use tf.compat.v1.disable_eager_execution instead.

2024-11-19 15:20:43,498 - WARNING - From c:\Github\Thesis-Project\timegan\main.py:131: The name tf.train.AdamOptimizer is deprecated. Please use tf.compat.v1.train.AdamOptimizer instead.

2024-11-19 16:00:19,614 - INFO - Starting parallel processing with 1 processes
2024-11-19 16:00:30,799 - INFO - Starting processing of file: u00024s00001_hw00004.svc
2024-11-19 16:00:32,869 - WARNING - From c:\Github\Thesis-Project\timegan\main.py:20: The name tf.disable_eager_execution is deprecated. Please use tf.compat.v1.disable_eager_execution instead.

2024-11-19 16:00:39,769 - WARNING - From c:\Github\Thesis-Project\timegan\main.py:131: The name tf.train.AdamOptimizer is deprecated. Please use tf.compat.v1.train.AdamOptimizer instead.

2024-11-19 16:01:14,518 - INFO - Starting parallel processing with 1 processes
2024-11-19 16:01:26,546 - INFO - Starting processing of file: u00024s00001_hw00004.svc
2024-11-19 16:01:28,269 - WARNING - From c:\Github\Thesis-Project\timegan\main.py:20: The name tf.disable_eager_execution is deprecated. Please use tf.compat.v1.disable_eager_execution instead.

2024-11-19 16:01:29,311 - ERROR - Error processing file u00024s00001_hw00004.svc: Exception encountered when calling RNN.call().

[1mlist index out of range[0m

Arguments received by RNN.call():
  • sequences=tf.Tensor(shape=(None, None, 24), dtype=float32)
  • initial_state=None
  • mask=None
  • training=False
2024-11-19 16:01:29,366 - INFO - 
Processing Summary:
2024-11-19 16:01:29,366 - INFO - Total files processed: 1
2024-11-19 16:01:29,366 - INFO - Successfully processed: 0
2024-11-19 16:01:29,366 - INFO - Failed to process: 1
2024-11-19 16:01:29,366 - INFO - Total wall time: 14.85 seconds
2024-11-19 16:01:29,366 - INFO - Total processing time: 0.00 seconds
2024-11-19 16:01:29,366 - ERROR - 
Failed files:
2024-11-19 16:01:29,366 - ERROR - u00024s00001_hw00004.svc: Exception encountered when calling RNN.call().

[1mlist index out of range[0m

Arguments received by RNN.call():
  • sequences=tf.Tensor(shape=(None, None, 24), dtype=float32)
  • initial_state=None
  • mask=None
  • training=False
2024-11-19 16:07:23,875 - INFO - Starting parallel processing with 1 processes
2024-11-19 16:07:35,907 - INFO - Starting processing of file: u00024s00001_hw00004.svc
2024-11-19 16:07:37,768 - WARNING - From c:\Github\Thesis-Project\timegan\main.py:20: The name tf.disable_eager_execution is deprecated. Please use tf.compat.v1.disable_eager_execution instead.

2024-11-19 16:07:44,170 - WARNING - From c:\Github\Thesis-Project\timegan\main.py:131: The name tf.train.AdamOptimizer is deprecated. Please use tf.compat.v1.train.AdamOptimizer instead.

2024-11-19 16:11:54,310 - ERROR - Error processing file u00024s00001_hw00004.svc: type numpy.ndarray doesn't define __round__ method
2024-11-19 16:11:54,435 - INFO - 
Processing Summary:
2024-11-19 16:11:54,435 - INFO - Total files processed: 1
2024-11-19 16:11:54,435 - INFO - Successfully processed: 0
2024-11-19 16:11:54,435 - INFO - Failed to process: 1
2024-11-19 16:11:54,435 - INFO - Total wall time: 270.56 seconds
2024-11-19 16:11:54,435 - INFO - Total processing time: 0.00 seconds
2024-11-19 16:11:54,439 - ERROR - 
Failed files:
2024-11-19 16:11:54,439 - ERROR - u00024s00001_hw00004.svc: type numpy.ndarray doesn't define __round__ method
2024-11-19 16:18:39,048 - INFO - Starting parallel processing with 1 processes
2024-11-19 16:18:51,706 - INFO - Starting processing of file: u00024s00001_hw00004.svc
2024-11-19 16:18:53,521 - WARNING - From c:\Github\Thesis-Project\timegan\main.py:20: The name tf.disable_eager_execution is deprecated. Please use tf.compat.v1.disable_eager_execution instead.

2024-11-19 16:18:54,650 - ERROR - Error processing file u00024s00001_hw00004.svc: Exception encountered when calling RNN.call().

[1mlist index out of range[0m

Arguments received by RNN.call():
  • sequences=tf.Tensor(shape=(None, None, 24), dtype=float32)
  • initial_state=None
  • mask=None
  • training=False
2024-11-19 16:18:54,650 - INFO - Starting processing of file: u00036s00001_hw00005.svc
2024-11-19 16:18:55,568 - ERROR - Error processing file u00036s00001_hw00005.svc: Exception encountered when calling RNN.call().

[1mlist index out of range[0m

Arguments received by RNN.call():
  • sequences=tf.Tensor(shape=(None, None, 24), dtype=float32)
  • initial_state=None
  • mask=None
  • training=False
2024-11-19 16:18:55,628 - INFO - 
Processing Summary:
2024-11-19 16:18:55,628 - INFO - Total files processed: 2
2024-11-19 16:18:55,628 - INFO - Successfully processed: 0
2024-11-19 16:18:55,628 - INFO - Failed to process: 2
2024-11-19 16:18:55,628 - INFO - Total wall time: 16.58 seconds
2024-11-19 16:18:55,628 - INFO - Total processing time: 0.00 seconds
2024-11-19 16:18:55,628 - ERROR - 
Failed files:
2024-11-19 16:18:55,628 - ERROR - u00024s00001_hw00004.svc: Exception encountered when calling RNN.call().

[1mlist index out of range[0m

Arguments received by RNN.call():
  • sequences=tf.Tensor(shape=(None, None, 24), dtype=float32)
  • initial_state=None
  • mask=None
  • training=False
2024-11-19 16:18:55,628 - ERROR - u00036s00001_hw00005.svc: Exception encountered when calling RNN.call().

[1mlist index out of range[0m

Arguments received by RNN.call():
  • sequences=tf.Tensor(shape=(None, None, 24), dtype=float32)
  • initial_state=None
  • mask=None
  • training=False
2024-11-19 16:19:22,255 - INFO - Starting parallel processing with 1 processes
2024-11-19 16:19:33,501 - INFO - Starting processing of file: u00024s00001_hw00004.svc
2024-11-19 16:19:35,118 - WARNING - From c:\Github\Thesis-Project\timegan\main.py:20: The name tf.disable_eager_execution is deprecated. Please use tf.compat.v1.disable_eager_execution instead.

2024-11-19 16:19:36,043 - ERROR - Error processing file u00024s00001_hw00004.svc: Exception encountered when calling RNN.call().

[1mlist index out of range[0m

Arguments received by RNN.call():
  • sequences=tf.Tensor(shape=(None, None, 24), dtype=float32)
  • initial_state=None
  • mask=None
  • training=False
2024-11-19 16:19:36,043 - INFO - Starting processing of file: u00036s00001_hw00005.svc
2024-11-19 16:19:36,944 - ERROR - Error processing file u00036s00001_hw00005.svc: Exception encountered when calling RNN.call().

[1mlist index out of range[0m

Arguments received by RNN.call():
  • sequences=tf.Tensor(shape=(None, None, 24), dtype=float32)
  • initial_state=None
  • mask=None
  • training=False
2024-11-19 16:19:37,014 - INFO - 
Processing Summary:
2024-11-19 16:19:37,014 - INFO - Total files processed: 2
2024-11-19 16:19:37,014 - INFO - Successfully processed: 0
2024-11-19 16:19:37,014 - INFO - Failed to process: 2
2024-11-19 16:19:37,014 - INFO - Total wall time: 14.76 seconds
2024-11-19 16:19:37,014 - INFO - Total processing time: 0.00 seconds
2024-11-19 16:19:37,014 - ERROR - 
Failed files:
2024-11-19 16:19:37,014 - ERROR - u00024s00001_hw00004.svc: Exception encountered when calling RNN.call().

[1mlist index out of range[0m

Arguments received by RNN.call():
  • sequences=tf.Tensor(shape=(None, None, 24), dtype=float32)
  • initial_state=None
  • mask=None
  • training=False
2024-11-19 16:19:37,014 - ERROR - u00036s00001_hw00005.svc: Exception encountered when calling RNN.call().

[1mlist index out of range[0m

Arguments received by RNN.call():
  • sequences=tf.Tensor(shape=(None, None, 24), dtype=float32)
  • initial_state=None
  • mask=None
  • training=False
2024-11-19 16:52:06,229 - INFO - Starting parallel processing with 2 processes
2024-11-19 16:52:18,063 - INFO - Starting processing of file: u00024s00001_hw00004.svc
2024-11-19 16:52:18,126 - INFO - Starting processing of file: u00036s00001_hw00005.svc
2024-11-19 16:52:20,045 - WARNING - From c:\Github\Thesis-Project\timegan\main.py:20: The name tf.disable_eager_execution is deprecated. Please use tf.compat.v1.disable_eager_execution instead.

2024-11-19 16:52:20,053 - WARNING - From c:\Github\Thesis-Project\timegan\main.py:20: The name tf.disable_eager_execution is deprecated. Please use tf.compat.v1.disable_eager_execution instead.

2024-11-19 16:52:21,233 - ERROR - Error processing file u00036s00001_hw00005.svc: Exception encountered when calling RNN.call().

[1mlist index out of range[0m

Arguments received by RNN.call():
  • sequences=tf.Tensor(shape=(None, None, 24), dtype=float32)
  • initial_state=None
  • mask=None
  • training=False
2024-11-19 16:52:21,238 - ERROR - Error processing file u00024s00001_hw00004.svc: Exception encountered when calling RNN.call().

[1mlist index out of range[0m

Arguments received by RNN.call():
  • sequences=tf.Tensor(shape=(None, None, 24), dtype=float32)
  • initial_state=None
  • mask=None
  • training=False
2024-11-19 16:52:21,306 - INFO - 
Processing Summary:
2024-11-19 16:52:21,306 - INFO - Total files processed: 2
2024-11-19 16:52:21,306 - INFO - Successfully processed: 0
2024-11-19 16:52:21,306 - INFO - Failed to process: 2
2024-11-19 16:52:21,306 - INFO - Total wall time: 15.08 seconds
2024-11-19 16:52:21,306 - INFO - Total processing time: 0.00 seconds
2024-11-19 16:52:21,306 - ERROR - 
Failed files:
2024-11-19 16:52:21,306 - ERROR - u00024s00001_hw00004.svc: Exception encountered when calling RNN.call().

[1mlist index out of range[0m

Arguments received by RNN.call():
  • sequences=tf.Tensor(shape=(None, None, 24), dtype=float32)
  • initial_state=None
  • mask=None
  • training=False
2024-11-19 16:52:21,306 - ERROR - u00036s00001_hw00005.svc: Exception encountered when calling RNN.call().

[1mlist index out of range[0m

Arguments received by RNN.call():
  • sequences=tf.Tensor(shape=(None, None, 24), dtype=float32)
  • initial_state=None
  • mask=None
  • training=False
2024-11-19 16:54:36,575 - INFO - Starting parallel processing with 1 processes
2024-11-19 16:54:47,141 - INFO - Starting processing of file: u00024s00001_hw00004.svc
2024-11-19 16:54:48,709 - WARNING - From c:\Github\Thesis-Project\timegan\main.py:20: The name tf.disable_eager_execution is deprecated. Please use tf.compat.v1.disable_eager_execution instead.

2024-11-19 16:54:49,620 - ERROR - Error processing file u00024s00001_hw00004.svc: Exception encountered when calling RNN.call().

[1mlist index out of range[0m

Arguments received by RNN.call():
  • sequences=tf.Tensor(shape=(None, None, 24), dtype=float32)
  • initial_state=None
  • mask=None
  • training=False
2024-11-19 16:54:49,620 - INFO - Starting processing of file: u00036s00001_hw00005.svc
2024-11-19 16:54:50,403 - ERROR - Error processing file u00036s00001_hw00005.svc: Exception encountered when calling RNN.call().

[1mlist index out of range[0m

Arguments received by RNN.call():
  • sequences=tf.Tensor(shape=(None, None, 24), dtype=float32)
  • initial_state=None
  • mask=None
  • training=False
2024-11-19 16:54:50,476 - INFO - 
Processing Summary:
2024-11-19 16:54:50,476 - INFO - Total files processed: 2
2024-11-19 16:54:50,476 - INFO - Successfully processed: 0
2024-11-19 16:54:50,476 - INFO - Failed to process: 2
2024-11-19 16:54:50,476 - INFO - Total wall time: 13.90 seconds
2024-11-19 16:54:50,476 - INFO - Total processing time: 0.00 seconds
2024-11-19 16:54:50,476 - ERROR - 
Failed files:
2024-11-19 16:54:50,476 - ERROR - u00024s00001_hw00004.svc: Exception encountered when calling RNN.call().

[1mlist index out of range[0m

Arguments received by RNN.call():
  • sequences=tf.Tensor(shape=(None, None, 24), dtype=float32)
  • initial_state=None
  • mask=None
  • training=False
2024-11-19 16:54:50,476 - ERROR - u00036s00001_hw00005.svc: Exception encountered when calling RNN.call().

[1mlist index out of range[0m

Arguments received by RNN.call():
  • sequences=tf.Tensor(shape=(None, None, 24), dtype=float32)
  • initial_state=None
  • mask=None
  • training=False
2024-11-19 16:55:14,268 - INFO - Starting parallel processing with 1 processes
2024-11-19 16:55:26,675 - INFO - Starting processing of file: u00024s00001_hw00004.svc
2024-11-19 16:55:28,528 - WARNING - From c:\Github\Thesis-Project\timegan\main.py:20: The name tf.disable_eager_execution is deprecated. Please use tf.compat.v1.disable_eager_execution instead.

2024-11-19 16:55:29,575 - ERROR - Error processing file u00024s00001_hw00004.svc: Exception encountered when calling RNN.call().

[1mlist index out of range[0m

Arguments received by RNN.call():
  • sequences=tf.Tensor(shape=(None, None, 24), dtype=float32)
  • initial_state=None
  • mask=None
  • training=False
2024-11-19 16:55:29,575 - INFO - Starting processing of file: u00036s00001_hw00005.svc
2024-11-19 16:55:30,514 - ERROR - Error processing file u00036s00001_hw00005.svc: Exception encountered when calling RNN.call().

[1mlist index out of range[0m

Arguments received by RNN.call():
  • sequences=tf.Tensor(shape=(None, None, 24), dtype=float32)
  • initial_state=None
  • mask=None
  • training=False
2024-11-19 16:55:30,592 - INFO - 
Processing Summary:
2024-11-19 16:55:30,592 - INFO - Total files processed: 2
2024-11-19 16:55:30,592 - INFO - Successfully processed: 0
2024-11-19 16:55:30,592 - INFO - Failed to process: 2
2024-11-19 16:55:30,592 - INFO - Total wall time: 16.32 seconds
2024-11-19 16:55:30,592 - INFO - Total processing time: 0.00 seconds
2024-11-19 16:55:30,592 - ERROR - 
Failed files:
2024-11-19 16:55:30,592 - ERROR - u00024s00001_hw00004.svc: Exception encountered when calling RNN.call().

[1mlist index out of range[0m

Arguments received by RNN.call():
  • sequences=tf.Tensor(shape=(None, None, 24), dtype=float32)
  • initial_state=None
  • mask=None
  • training=False
2024-11-19 16:55:30,592 - ERROR - u00036s00001_hw00005.svc: Exception encountered when calling RNN.call().

[1mlist index out of range[0m

Arguments received by RNN.call():
  • sequences=tf.Tensor(shape=(None, None, 24), dtype=float32)
  • initial_state=None
  • mask=None
  • training=False
2024-11-19 16:56:16,786 - INFO - Starting parallel processing with 1 processes
2024-11-19 16:56:28,228 - INFO - Starting processing of file: u00024s00001_hw00004.svc
2024-11-19 16:56:29,850 - WARNING - From c:\Github\Thesis-Project\timegan\main.py:20: The name tf.disable_eager_execution is deprecated. Please use tf.compat.v1.disable_eager_execution instead.

2024-11-19 16:56:35,566 - WARNING - From c:\Github\Thesis-Project\timegan\main.py:131: The name tf.train.AdamOptimizer is deprecated. Please use tf.compat.v1.train.AdamOptimizer instead.

2024-11-19 16:57:20,077 - INFO - Starting parallel processing with 1 processes
2024-11-19 16:57:34,032 - INFO - Starting processing of file: u00024s00001_hw00004.svc
2024-11-19 16:57:35,800 - WARNING - From c:\Github\Thesis-Project\timegan\main.py:20: The name tf.disable_eager_execution is deprecated. Please use tf.compat.v1.disable_eager_execution instead.

2024-11-19 16:57:40,086 - WARNING - From c:\Github\Thesis-Project\timegan\main.py:131: The name tf.train.AdamOptimizer is deprecated. Please use tf.compat.v1.train.AdamOptimizer instead.

2024-11-19 16:58:34,608 - INFO - Starting parallel processing with 1 processes
2024-11-19 16:58:45,986 - INFO - Starting processing of file: u00024s00001_hw00004.svc
2024-11-19 16:58:47,653 - WARNING - From c:\Github\Thesis-Project\timegan\main.py:20: The name tf.disable_eager_execution is deprecated. Please use tf.compat.v1.disable_eager_execution instead.

2024-11-19 16:58:51,772 - WARNING - From c:\Github\Thesis-Project\timegan\main.py:131: The name tf.train.AdamOptimizer is deprecated. Please use tf.compat.v1.train.AdamOptimizer instead.

2024-11-19 17:01:48,364 - ERROR - Error processing file u00024s00001_hw00004.svc: type numpy.ndarray doesn't define __round__ method
2024-11-19 17:01:48,364 - INFO - Starting processing of file: u00036s00001_hw00005.svc
2024-11-19 17:05:40,907 - ERROR - Error processing file u00036s00001_hw00005.svc: type numpy.ndarray doesn't define __round__ method
2024-11-19 17:05:40,997 - INFO - 
Processing Summary:
2024-11-19 17:05:40,997 - INFO - Total files processed: 2
2024-11-19 17:05:40,997 - INFO - Successfully processed: 0
2024-11-19 17:05:40,997 - INFO - Failed to process: 2
2024-11-19 17:05:40,997 - INFO - Total wall time: 426.39 seconds
2024-11-19 17:05:40,997 - INFO - Total processing time: 0.00 seconds
2024-11-19 17:05:40,997 - ERROR - 
Failed files:
2024-11-19 17:05:40,997 - ERROR - u00024s00001_hw00004.svc: type numpy.ndarray doesn't define __round__ method
2024-11-19 17:05:40,997 - ERROR - u00036s00001_hw00005.svc: type numpy.ndarray doesn't define __round__ method
2024-11-19 17:13:04,144 - INFO - Starting parallel processing with 1 processes
2024-11-19 17:13:13,359 - INFO - Starting processing of file: u00036s00001_hw00005.svc
2024-11-19 17:13:14,844 - WARNING - From c:\Github\Thesis-Project\timegan\main.py:20: The name tf.disable_eager_execution is deprecated. Please use tf.compat.v1.disable_eager_execution instead.

2024-11-19 17:13:18,375 - WARNING - From c:\Github\Thesis-Project\timegan\main.py:131: The name tf.train.AdamOptimizer is deprecated. Please use tf.compat.v1.train.AdamOptimizer instead.

2024-11-19 17:15:34,707 - ERROR - Error processing file u00036s00001_hw00005.svc: type numpy.ndarray doesn't define __round__ method
2024-11-19 17:15:34,785 - INFO - 
Processing Summary:
2024-11-19 17:15:34,785 - INFO - Total files processed: 1
2024-11-19 17:15:34,785 - INFO - Successfully processed: 0
2024-11-19 17:15:34,785 - INFO - Failed to process: 1
2024-11-19 17:15:34,785 - INFO - Total wall time: 150.64 seconds
2024-11-19 17:15:34,785 - INFO - Total processing time: 0.00 seconds
2024-11-19 17:15:34,785 - ERROR - 
Failed files:
2024-11-19 17:15:34,785 - ERROR - u00036s00001_hw00005.svc: type numpy.ndarray doesn't define __round__ method
2024-11-19 21:48:22,048 - INFO - Starting parallel processing with 1 processes
2024-11-19 21:48:35,261 - INFO - Starting processing of file: u00036s00001_hw00005.svc
2024-11-19 21:48:37,135 - WARNING - From c:\Github\Thesis-Project\timegan\main.py:20: The name tf.disable_eager_execution is deprecated. Please use tf.compat.v1.disable_eager_execution instead.

2024-11-19 21:48:42,454 - WARNING - From c:\Github\Thesis-Project\timegan\main.py:131: The name tf.train.AdamOptimizer is deprecated. Please use tf.compat.v1.train.AdamOptimizer instead.

2024-11-19 21:49:47,592 - ERROR - Error processing file u00036s00001_hw00005.svc: type numpy.ndarray doesn't define __round__ method
2024-11-19 21:49:47,678 - INFO - 
Processing Summary:
2024-11-19 21:49:47,678 - INFO - Total files processed: 1
2024-11-19 21:49:47,679 - INFO - Successfully processed: 0
2024-11-19 21:49:47,679 - INFO - Failed to process: 1
2024-11-19 21:49:47,679 - INFO - Total wall time: 85.63 seconds
2024-11-19 21:49:47,679 - INFO - Total processing time: 0.00 seconds
2024-11-19 21:49:47,679 - ERROR - 
Failed files:
2024-11-19 21:49:47,679 - ERROR - u00036s00001_hw00005.svc: type numpy.ndarray doesn't define __round__ method
2024-11-19 22:05:19,837 - INFO - Starting parallel processing with 2 processes
2024-11-19 22:05:33,729 - INFO - Starting processing of file: u00036s00001_hw00005.svc
2024-11-19 22:05:35,704 - WARNING - From c:\Github\Thesis-Project\timegan\main.py:20: The name tf.disable_eager_execution is deprecated. Please use tf.compat.v1.disable_eager_execution instead.

2024-11-19 22:05:40,863 - WARNING - From c:\Github\Thesis-Project\timegan\main.py:131: The name tf.train.AdamOptimizer is deprecated. Please use tf.compat.v1.train.AdamOptimizer instead.

2024-11-19 22:05:52,846 - ERROR - Error processing file u00036s00001_hw00005.svc: type numpy.ndarray doesn't define __round__ method
2024-11-19 22:05:52,949 - INFO - 
Processing Summary:
2024-11-19 22:05:52,949 - INFO - Total files processed: 1
2024-11-19 22:05:52,950 - INFO - Successfully processed: 0
2024-11-19 22:05:52,950 - INFO - Failed to process: 1
2024-11-19 22:05:52,950 - INFO - Total wall time: 33.11 seconds
2024-11-19 22:05:52,951 - INFO - Total processing time: 0.00 seconds
2024-11-19 22:05:52,951 - ERROR - 
Failed files:
2024-11-19 22:05:52,951 - ERROR - u00036s00001_hw00005.svc: type numpy.ndarray doesn't define __round__ method
2024-11-19 22:09:29,006 - INFO - Starting parallel processing with 2 processes
2024-11-19 22:09:45,183 - INFO - Starting processing of file: u00036s00001_hw00005.svc
2024-11-19 22:09:47,501 - WARNING - From c:\Github\Thesis-Project\timegan\main.py:20: The name tf.disable_eager_execution is deprecated. Please use tf.compat.v1.disable_eager_execution instead.

2024-11-19 22:09:55,610 - WARNING - From c:\Github\Thesis-Project\timegan\main.py:131: The name tf.train.AdamOptimizer is deprecated. Please use tf.compat.v1.train.AdamOptimizer instead.

2024-11-19 22:10:46,584 - INFO - Completed processing file u00036s00001_hw00005.svc. Time taken: 61.40 seconds
2024-11-19 22:10:46,688 - INFO - 
Processing Summary:
2024-11-19 22:10:46,688 - INFO - Total files processed: 1
2024-11-19 22:10:46,689 - INFO - Successfully processed: 1
2024-11-19 22:10:46,689 - INFO - Failed to process: 0
2024-11-19 22:10:46,689 - INFO - Total wall time: 77.68 seconds
2024-11-19 22:10:46,689 - INFO - Total processing time: 61.40 seconds
2024-11-19 22:16:33,670 - INFO - Starting parallel processing with 2 processes
2024-11-19 22:16:47,969 - INFO - Starting processing of file: u00036s00001_hw00005.svc
2024-11-19 22:16:50,020 - WARNING - From c:\Github\Thesis-Project\timegan\main.py:20: The name tf.disable_eager_execution is deprecated. Please use tf.compat.v1.disable_eager_execution instead.

2024-11-19 22:16:57,303 - WARNING - From c:\Github\Thesis-Project\timegan\main.py:131: The name tf.train.AdamOptimizer is deprecated. Please use tf.compat.v1.train.AdamOptimizer instead.

2024-11-21 13:37:33,239 - WARNING - From c:\Github\Thesis-Project\timegan\main.py:55: The name tf.disable_eager_execution is deprecated. Please use tf.compat.v1.disable_eager_execution instead.

2024-11-21 13:42:23,440 - WARNING - From c:\Github\Thesis-Project\timegan\main.py:90: The name tf.disable_eager_execution is deprecated. Please use tf.compat.v1.disable_eager_execution instead.

2024-11-21 13:42:25,057 - WARNING - From c:\Github\Thesis-Project\timegan\main.py:84: The name tf.train.AdamOptimizer is deprecated. Please use tf.compat.v1.train.AdamOptimizer instead.

2024-11-21 13:51:01,043 - INFO - Restoring parameters from ./timegan/saved_model\timegan_model
2024-11-21 14:03:39,149 - WARNING - From c:\Github\Thesis-Project\timegan\main.py:238: The name tf.Session is deprecated. Please use tf.compat.v1.Session instead.

2024-11-21 14:11:30,708 - WARNING - From c:\Github\Thesis-Project\timegan\main.py:18: The name tf.disable_eager_execution is deprecated. Please use tf.compat.v1.disable_eager_execution instead.

2024-11-21 14:11:32,056 - WARNING - From c:\Github\Thesis-Project\timegan\main.py:80: The name tf.train.AdamOptimizer is deprecated. Please use tf.compat.v1.train.AdamOptimizer instead.

2024-11-21 14:25:36,897 - WARNING - From c:\Github\Thesis-Project\timegan\main.py:18: The name tf.disable_eager_execution is deprecated. Please use tf.compat.v1.disable_eager_execution instead.

2024-11-21 14:25:38,417 - WARNING - From c:\Github\Thesis-Project\timegan\main.py:80: The name tf.train.AdamOptimizer is deprecated. Please use tf.compat.v1.train.AdamOptimizer instead.

2024-11-21 14:30:04,683 - INFO - Restoring parameters from ./timegan/saved_model\timegan_model
2024-11-21 14:34:36,109 - WARNING - From c:\Github\Thesis-Project\timegan\main.py:18: The name tf.disable_eager_execution is deprecated. Please use tf.compat.v1.disable_eager_execution instead.

2024-11-21 14:34:37,515 - WARNING - From c:\Github\Thesis-Project\timegan\main.py:80: The name tf.train.AdamOptimizer is deprecated. Please use tf.compat.v1.train.AdamOptimizer instead.

2024-11-21 14:35:47,674 - INFO - Restoring parameters from ./timegan/saved_model\timegan_model
2024-11-21 14:47:00,371 - WARNING - From c:\Github\Thesis-Project\timegan\main.py:18: The name tf.disable_eager_execution is deprecated. Please use tf.compat.v1.disable_eager_execution instead.

2024-11-21 14:47:01,682 - WARNING - From c:\Github\Thesis-Project\timegan\main.py:80: The name tf.train.AdamOptimizer is deprecated. Please use tf.compat.v1.train.AdamOptimizer instead.

2024-11-21 14:48:05,341 - INFO - Restoring parameters from ./timegan/saved_model\timegan_model
2024-11-21 14:48:06,203 - ERROR - An error occurred: Restoring from checkpoint failed. This is most likely due to a Variable name or other graph key that is missing from the checkpoint. Please ensure that you have not altered the graph expected based on the checkpoint. Original error:

Graph execution error:

Detected at node 'save/RestoreV2' defined at (most recent call last):
    File "c:\Github\Thesis-Project\timegan\main.py", line 312, in <module>
    File "c:\Github\Thesis-Project\timegan\main.py", line 285, in main
    File "c:\Github\Thesis-Project\timegan\main.py", line 199, in load_model
Node: 'save/RestoreV2'
Key embedder/rnn_2/stacked_rnn_cells_2/gru_cell_6/bias not found in checkpoint
	 [[{{node save/RestoreV2}}]]

Original stack trace for 'save/RestoreV2':
  File "c:\Github\Thesis-Project\timegan\main.py", line 312, in <module>
  File "c:\Github\Thesis-Project\timegan\main.py", line 285, in main
  File "c:\Github\Thesis-Project\timegan\main.py", line 199, in load_model
  File "C:\Users\annek\AppData\Roaming\Python\Python312\site-packages\tensorflow\python\training\saver.py", line 934, in __init__
  File "C:\Users\annek\AppData\Roaming\Python\Python312\site-packages\tensorflow\python\training\saver.py", line 946, in build
  File "C:\Users\annek\AppData\Roaming\Python\Python312\site-packages\tensorflow\python\training\saver.py", line 974, in _build
  File "C:\Users\annek\AppData\Roaming\Python\Python312\site-packages\tensorflow\python\training\saver.py", line 543, in _build_internal
  File "C:\Users\annek\AppData\Roaming\Python\Python312\site-packages\tensorflow\python\training\saver.py", line 360, in _AddRestoreOps
  File "C:\Users\annek\AppData\Roaming\Python\Python312\site-packages\tensorflow\python\training\saver.py", line 611, in bulk_restore
  File "C:\Users\annek\AppData\Roaming\Python\Python312\site-packages\tensorflow\python\ops\gen_io_ops.py", line 1610, in restore_v2
  File "C:\Users\annek\AppData\Roaming\Python\Python312\site-packages\tensorflow\python\framework\op_def_library.py", line 796, in _apply_op_helper
  File "C:\Users\annek\AppData\Roaming\Python\Python312\site-packages\tensorflow\python\framework\ops.py", line 2682, in _create_op_internal
  File "C:\Users\annek\AppData\Roaming\Python\Python312\site-packages\tensorflow\python\framework\ops.py", line 1177, in from_node_def
Traceback (most recent call last):
  File "C:\Users\annek\AppData\Roaming\Python\Python312\site-packages\tensorflow\python\client\session.py", line 1401, in _do_call
    return fn(*args)
           ^^^^^^^^^
  File "C:\Users\annek\AppData\Roaming\Python\Python312\site-packages\tensorflow\python\client\session.py", line 1384, in _run_fn
    return self._call_tf_sessionrun(options, feed_dict, fetch_list,
           ^^^^^^^^^^^^^^^^^^^^^^^^^^^^^^^^^^^^^^^^^^^^^^^^^^^^^^^^
  File "C:\Users\annek\AppData\Roaming\Python\Python312\site-packages\tensorflow\python\client\session.py", line 1477, in _call_tf_sessionrun
    return tf_session.TF_SessionRun_wrapper(self._session, options, feed_dict,
           ^^^^^^^^^^^^^^^^^^^^^^^^^^^^^^^^^^^^^^^^^^^^^^^^^^^^^^^^^^^^^^^^^^^
tensorflow.python.framework.errors_impl.NotFoundError: Key embedder/rnn_2/stacked_rnn_cells_2/gru_cell_6/bias not found in checkpoint
	 [[{{node save/RestoreV2}}]]

During handling of the above exception, another exception occurred:

Traceback (most recent call last):
  File "C:\Users\annek\AppData\Roaming\Python\Python312\site-packages\tensorflow\python\training\saver.py", line 1422, in restore
    sess.run(self.saver_def.restore_op_name,
  File "C:\Users\annek\AppData\Roaming\Python\Python312\site-packages\tensorflow\python\client\session.py", line 971, in run
    result = self._run(None, fetches, feed_dict, options_ptr,
             ^^^^^^^^^^^^^^^^^^^^^^^^^^^^^^^^^^^^^^^^^^^^^^^^
  File "C:\Users\annek\AppData\Roaming\Python\Python312\site-packages\tensorflow\python\client\session.py", line 1214, in _run
    results = self._do_run(handle, final_targets, final_fetches,
              ^^^^^^^^^^^^^^^^^^^^^^^^^^^^^^^^^^^^^^^^^^^^^^^^^^
  File "C:\Users\annek\AppData\Roaming\Python\Python312\site-packages\tensorflow\python\client\session.py", line 1394, in _do_run
    return self._do_call(_run_fn, feeds, fetches, targets, options,
           ^^^^^^^^^^^^^^^^^^^^^^^^^^^^^^^^^^^^^^^^^^^^^^^^^^^^^^^^
  File "C:\Users\annek\AppData\Roaming\Python\Python312\site-packages\tensorflow\python\client\session.py", line 1420, in _do_call
    raise type(e)(node_def, op, message)  # pylint: disable=no-value-for-parameter
    ^^^^^^^^^^^^^^^^^^^^^^^^^^^^^^^^^^^^
tensorflow.python.framework.errors_impl.NotFoundError: Graph execution error:

Detected at node 'save/RestoreV2' defined at (most recent call last):
    File "c:\Github\Thesis-Project\timegan\main.py", line 312, in <module>
    File "c:\Github\Thesis-Project\timegan\main.py", line 285, in main
    File "c:\Github\Thesis-Project\timegan\main.py", line 199, in load_model
Node: 'save/RestoreV2'
Key embedder/rnn_2/stacked_rnn_cells_2/gru_cell_6/bias not found in checkpoint
	 [[{{node save/RestoreV2}}]]

Original stack trace for 'save/RestoreV2':
  File "c:\Github\Thesis-Project\timegan\main.py", line 312, in <module>
  File "c:\Github\Thesis-Project\timegan\main.py", line 285, in main
  File "c:\Github\Thesis-Project\timegan\main.py", line 199, in load_model
  File "C:\Users\annek\AppData\Roaming\Python\Python312\site-packages\tensorflow\python\training\saver.py", line 934, in __init__
  File "C:\Users\annek\AppData\Roaming\Python\Python312\site-packages\tensorflow\python\training\saver.py", line 946, in build
  File "C:\Users\annek\AppData\Roaming\Python\Python312\site-packages\tensorflow\python\training\saver.py", line 974, in _build
  File "C:\Users\annek\AppData\Roaming\Python\Python312\site-packages\tensorflow\python\training\saver.py", line 543, in _build_internal
  File "C:\Users\annek\AppData\Roaming\Python\Python312\site-packages\tensorflow\python\training\saver.py", line 360, in _AddRestoreOps
  File "C:\Users\annek\AppData\Roaming\Python\Python312\site-packages\tensorflow\python\training\saver.py", line 611, in bulk_restore
  File "C:\Users\annek\AppData\Roaming\Python\Python312\site-packages\tensorflow\python\ops\gen_io_ops.py", line 1610, in restore_v2
  File "C:\Users\annek\AppData\Roaming\Python\Python312\site-packages\tensorflow\python\framework\op_def_library.py", line 796, in _apply_op_helper
  File "C:\Users\annek\AppData\Roaming\Python\Python312\site-packages\tensorflow\python\framework\ops.py", line 2682, in _create_op_internal
  File "C:\Users\annek\AppData\Roaming\Python\Python312\site-packages\tensorflow\python\framework\ops.py", line 1177, in from_node_def


During handling of the above exception, another exception occurred:

Traceback (most recent call last):
  File "C:\Users\annek\AppData\Roaming\Python\Python312\site-packages\tensorflow\python\training\py_checkpoint_reader.py", line 66, in get_tensor
    return CheckpointReader.CheckpointReader_GetTensor(
           ^^^^^^^^^^^^^^^^^^^^^^^^^^^^^^^^^^^^^^^^^^^^
RuntimeError: Key _CHECKPOINTABLE_OBJECT_GRAPH not found in checkpoint

During handling of the above exception, another exception occurred:

Traceback (most recent call last):
  File "C:\Users\annek\AppData\Roaming\Python\Python312\site-packages\tensorflow\python\training\saver.py", line 1433, in restore
    names_to_keys = object_graph_key_mapping(save_path)
                    ^^^^^^^^^^^^^^^^^^^^^^^^^^^^^^^^^^^
  File "C:\Users\annek\AppData\Roaming\Python\Python312\site-packages\tensorflow\python\training\saver.py", line 1755, in object_graph_key_mapping
    object_graph_string = reader.get_tensor(trackable.OBJECT_GRAPH_PROTO_KEY)
                          ^^^^^^^^^^^^^^^^^^^^^^^^^^^^^^^^^^^^^^^^^^^^^^^^^^^
  File "C:\Users\annek\AppData\Roaming\Python\Python312\site-packages\tensorflow\python\training\py_checkpoint_reader.py", line 71, in get_tensor
    error_translator(e)
  File "C:\Users\annek\AppData\Roaming\Python\Python312\site-packages\tensorflow\python\training\py_checkpoint_reader.py", line 31, in error_translator
    raise errors_impl.NotFoundError(None, None, error_message)
tensorflow.python.framework.errors_impl.NotFoundError: Key _CHECKPOINTABLE_OBJECT_GRAPH not found in checkpoint

During handling of the above exception, another exception occurred:

Traceback (most recent call last):
  File "c:\Github\Thesis-Project\timegan\main.py", line 285, in main
    loaded_timegan.load_model(model_save_dir)
  File "c:\Github\Thesis-Project\timegan\main.py", line 200, in load_model
    saver.restore(self.session, os.path.join(save_dir, 'timegan_model'))
  File "C:\Users\annek\AppData\Roaming\Python\Python312\site-packages\tensorflow\python\training\saver.py", line 1438, in restore
    raise _wrap_restore_error_with_msg(
tensorflow.python.framework.errors_impl.NotFoundError: Restoring from checkpoint failed. This is most likely due to a Variable name or other graph key that is missing from the checkpoint. Please ensure that you have not altered the graph expected based on the checkpoint. Original error:

Graph execution error:

Detected at node 'save/RestoreV2' defined at (most recent call last):
    File "c:\Github\Thesis-Project\timegan\main.py", line 312, in <module>
    File "c:\Github\Thesis-Project\timegan\main.py", line 285, in main
    File "c:\Github\Thesis-Project\timegan\main.py", line 199, in load_model
Node: 'save/RestoreV2'
Key embedder/rnn_2/stacked_rnn_cells_2/gru_cell_6/bias not found in checkpoint
	 [[{{node save/RestoreV2}}]]

Original stack trace for 'save/RestoreV2':
  File "c:\Github\Thesis-Project\timegan\main.py", line 312, in <module>
  File "c:\Github\Thesis-Project\timegan\main.py", line 285, in main
  File "c:\Github\Thesis-Project\timegan\main.py", line 199, in load_model
  File "C:\Users\annek\AppData\Roaming\Python\Python312\site-packages\tensorflow\python\training\saver.py", line 934, in __init__
  File "C:\Users\annek\AppData\Roaming\Python\Python312\site-packages\tensorflow\python\training\saver.py", line 946, in build
  File "C:\Users\annek\AppData\Roaming\Python\Python312\site-packages\tensorflow\python\training\saver.py", line 974, in _build
  File "C:\Users\annek\AppData\Roaming\Python\Python312\site-packages\tensorflow\python\training\saver.py", line 543, in _build_internal
  File "C:\Users\annek\AppData\Roaming\Python\Python312\site-packages\tensorflow\python\training\saver.py", line 360, in _AddRestoreOps
  File "C:\Users\annek\AppData\Roaming\Python\Python312\site-packages\tensorflow\python\training\saver.py", line 611, in bulk_restore
  File "C:\Users\annek\AppData\Roaming\Python\Python312\site-packages\tensorflow\python\ops\gen_io_ops.py", line 1610, in restore_v2
  File "C:\Users\annek\AppData\Roaming\Python\Python312\site-packages\tensorflow\python\framework\op_def_library.py", line 796, in _apply_op_helper
  File "C:\Users\annek\AppData\Roaming\Python\Python312\site-packages\tensorflow\python\framework\ops.py", line 2682, in _create_op_internal
  File "C:\Users\annek\AppData\Roaming\Python\Python312\site-packages\tensorflow\python\framework\ops.py", line 1177, in from_node_def

2024-11-21 14:52:53,869 - WARNING - From c:\Github\Thesis-Project\timegan\main.py:18: The name tf.disable_eager_execution is deprecated. Please use tf.compat.v1.disable_eager_execution instead.

2024-11-21 14:52:53,885 - ERROR - An error occurred: `MultiRNNCell` is not available with Keras 3.
Traceback (most recent call last):
  File "c:\Github\Thesis-Project\timegan\main.py", line 320, in main
    timegan.train(train_data)
  File "c:\Github\Thesis-Project\timegan\main.py", line 160, in train
    self._build_graph(dim)
  File "c:\Github\Thesis-Project\timegan\main.py", line 75, in _build_graph
    multi_cell = tf.compat.v1.nn.rnn_cell.MultiRNNCell(
                 ^^^^^^^^^^^^^^^^^^^^^^^^^^^^^^^^^^^^^
  File "C:\Users\annek\AppData\Roaming\Python\Python312\site-packages\tensorflow\python\util\lazy_loader.py", line 207, in __getattr__
    raise AttributeError(
AttributeError: `MultiRNNCell` is not available with Keras 3.
2024-11-21 14:58:39,036 - WARNING - From c:\Github\Thesis-Project\timegan\main.py:18: The name tf.disable_eager_execution is deprecated. Please use tf.compat.v1.disable_eager_execution instead.

2024-11-21 14:58:39,903 - ERROR - An error occurred: too many values to unpack (expected 2)
Traceback (most recent call last):
  File "c:\Github\Thesis-Project\timegan\main.py", line 296, in main
    timegan.train(train_data)
  File "c:\Github\Thesis-Project\timegan\main.py", line 136, in train
    self._build_graph(dim)
  File "c:\Github\Thesis-Project\timegan\main.py", line 79, in _build_graph
    outputs, _ = tf.keras.layers.RNN(stacked_cells, return_sequences=True, return_state=True)(self.X, initial_state=initial_state)
    ^^^^^^^^^^
ValueError: too many values to unpack (expected 2)
2024-11-21 18:06:11,601 - WARNING - From c:\Github\Thesis-Project\timegan\main.py:126: The name tf.reset_default_graph is deprecated. Please use tf.compat.v1.reset_default_graph instead.

2024-11-21 18:06:13,355 - WARNING - From c:\Github\Thesis-Project\timegan\main.py:111: The name tf.train.AdamOptimizer is deprecated. Please use tf.compat.v1.train.AdamOptimizer instead.

2024-11-21 18:07:26,777 - INFO - Restoring parameters from ./timegan/saved_model\timegan_model
2024-11-21 18:07:27,778 - ERROR - An error occurred: Restoring from checkpoint failed. This is most likely due to a Variable name or other graph key that is missing from the checkpoint. Please ensure that you have not altered the graph expected based on the checkpoint. Original error:

Graph execution error:

Detected at node 'save/RestoreV2' defined at (most recent call last):
    File "c:\Github\Thesis-Project\timegan\main.py", line 338, in <module>
    File "c:\Github\Thesis-Project\timegan\main.py", line 311, in main
    File "c:\Github\Thesis-Project\timegan\main.py", line 224, in load_model
Node: 'save/RestoreV2'
Key embedder/rnn_2/stacked_rnn_cells_2/gru_cell_6/bias not found in checkpoint
	 [[{{node save/RestoreV2}}]]

Original stack trace for 'save/RestoreV2':
  File "c:\Github\Thesis-Project\timegan\main.py", line 338, in <module>
  File "c:\Github\Thesis-Project\timegan\main.py", line 311, in main
  File "c:\Github\Thesis-Project\timegan\main.py", line 224, in load_model
  File "C:\Users\annek\AppData\Roaming\Python\Python312\site-packages\tensorflow\python\training\saver.py", line 934, in __init__
  File "C:\Users\annek\AppData\Roaming\Python\Python312\site-packages\tensorflow\python\training\saver.py", line 946, in build
  File "C:\Users\annek\AppData\Roaming\Python\Python312\site-packages\tensorflow\python\training\saver.py", line 974, in _build
  File "C:\Users\annek\AppData\Roaming\Python\Python312\site-packages\tensorflow\python\training\saver.py", line 543, in _build_internal
  File "C:\Users\annek\AppData\Roaming\Python\Python312\site-packages\tensorflow\python\training\saver.py", line 360, in _AddRestoreOps
  File "C:\Users\annek\AppData\Roaming\Python\Python312\site-packages\tensorflow\python\training\saver.py", line 611, in bulk_restore
  File "C:\Users\annek\AppData\Roaming\Python\Python312\site-packages\tensorflow\python\ops\gen_io_ops.py", line 1610, in restore_v2
  File "C:\Users\annek\AppData\Roaming\Python\Python312\site-packages\tensorflow\python\framework\op_def_library.py", line 796, in _apply_op_helper
  File "C:\Users\annek\AppData\Roaming\Python\Python312\site-packages\tensorflow\python\framework\ops.py", line 2682, in _create_op_internal
  File "C:\Users\annek\AppData\Roaming\Python\Python312\site-packages\tensorflow\python\framework\ops.py", line 1177, in from_node_def
Traceback (most recent call last):
  File "C:\Users\annek\AppData\Roaming\Python\Python312\site-packages\tensorflow\python\client\session.py", line 1401, in _do_call
    return fn(*args)
           ^^^^^^^^^
  File "C:\Users\annek\AppData\Roaming\Python\Python312\site-packages\tensorflow\python\client\session.py", line 1384, in _run_fn
    return self._call_tf_sessionrun(options, feed_dict, fetch_list,
           ^^^^^^^^^^^^^^^^^^^^^^^^^^^^^^^^^^^^^^^^^^^^^^^^^^^^^^^^
  File "C:\Users\annek\AppData\Roaming\Python\Python312\site-packages\tensorflow\python\client\session.py", line 1477, in _call_tf_sessionrun
    return tf_session.TF_SessionRun_wrapper(self._session, options, feed_dict,
           ^^^^^^^^^^^^^^^^^^^^^^^^^^^^^^^^^^^^^^^^^^^^^^^^^^^^^^^^^^^^^^^^^^^
tensorflow.python.framework.errors_impl.NotFoundError: Key embedder/rnn_2/stacked_rnn_cells_2/gru_cell_6/bias not found in checkpoint
	 [[{{node save/RestoreV2}}]]

During handling of the above exception, another exception occurred:

Traceback (most recent call last):
  File "C:\Users\annek\AppData\Roaming\Python\Python312\site-packages\tensorflow\python\training\saver.py", line 1422, in restore
    sess.run(self.saver_def.restore_op_name,
  File "C:\Users\annek\AppData\Roaming\Python\Python312\site-packages\tensorflow\python\client\session.py", line 971, in run
    result = self._run(None, fetches, feed_dict, options_ptr,
             ^^^^^^^^^^^^^^^^^^^^^^^^^^^^^^^^^^^^^^^^^^^^^^^^
  File "C:\Users\annek\AppData\Roaming\Python\Python312\site-packages\tensorflow\python\client\session.py", line 1214, in _run
    results = self._do_run(handle, final_targets, final_fetches,
              ^^^^^^^^^^^^^^^^^^^^^^^^^^^^^^^^^^^^^^^^^^^^^^^^^^
  File "C:\Users\annek\AppData\Roaming\Python\Python312\site-packages\tensorflow\python\client\session.py", line 1394, in _do_run
    return self._do_call(_run_fn, feeds, fetches, targets, options,
           ^^^^^^^^^^^^^^^^^^^^^^^^^^^^^^^^^^^^^^^^^^^^^^^^^^^^^^^^
  File "C:\Users\annek\AppData\Roaming\Python\Python312\site-packages\tensorflow\python\client\session.py", line 1420, in _do_call
    raise type(e)(node_def, op, message)  # pylint: disable=no-value-for-parameter
    ^^^^^^^^^^^^^^^^^^^^^^^^^^^^^^^^^^^^
tensorflow.python.framework.errors_impl.NotFoundError: Graph execution error:

Detected at node 'save/RestoreV2' defined at (most recent call last):
    File "c:\Github\Thesis-Project\timegan\main.py", line 338, in <module>
    File "c:\Github\Thesis-Project\timegan\main.py", line 311, in main
    File "c:\Github\Thesis-Project\timegan\main.py", line 224, in load_model
Node: 'save/RestoreV2'
Key embedder/rnn_2/stacked_rnn_cells_2/gru_cell_6/bias not found in checkpoint
	 [[{{node save/RestoreV2}}]]

Original stack trace for 'save/RestoreV2':
  File "c:\Github\Thesis-Project\timegan\main.py", line 338, in <module>
  File "c:\Github\Thesis-Project\timegan\main.py", line 311, in main
  File "c:\Github\Thesis-Project\timegan\main.py", line 224, in load_model
  File "C:\Users\annek\AppData\Roaming\Python\Python312\site-packages\tensorflow\python\training\saver.py", line 934, in __init__
  File "C:\Users\annek\AppData\Roaming\Python\Python312\site-packages\tensorflow\python\training\saver.py", line 946, in build
  File "C:\Users\annek\AppData\Roaming\Python\Python312\site-packages\tensorflow\python\training\saver.py", line 974, in _build
  File "C:\Users\annek\AppData\Roaming\Python\Python312\site-packages\tensorflow\python\training\saver.py", line 543, in _build_internal
  File "C:\Users\annek\AppData\Roaming\Python\Python312\site-packages\tensorflow\python\training\saver.py", line 360, in _AddRestoreOps
  File "C:\Users\annek\AppData\Roaming\Python\Python312\site-packages\tensorflow\python\training\saver.py", line 611, in bulk_restore
  File "C:\Users\annek\AppData\Roaming\Python\Python312\site-packages\tensorflow\python\ops\gen_io_ops.py", line 1610, in restore_v2
  File "C:\Users\annek\AppData\Roaming\Python\Python312\site-packages\tensorflow\python\framework\op_def_library.py", line 796, in _apply_op_helper
  File "C:\Users\annek\AppData\Roaming\Python\Python312\site-packages\tensorflow\python\framework\ops.py", line 2682, in _create_op_internal
  File "C:\Users\annek\AppData\Roaming\Python\Python312\site-packages\tensorflow\python\framework\ops.py", line 1177, in from_node_def


During handling of the above exception, another exception occurred:

Traceback (most recent call last):
  File "C:\Users\annek\AppData\Roaming\Python\Python312\site-packages\tensorflow\python\training\py_checkpoint_reader.py", line 66, in get_tensor
    return CheckpointReader.CheckpointReader_GetTensor(
           ^^^^^^^^^^^^^^^^^^^^^^^^^^^^^^^^^^^^^^^^^^^^
RuntimeError: Key _CHECKPOINTABLE_OBJECT_GRAPH not found in checkpoint

During handling of the above exception, another exception occurred:

Traceback (most recent call last):
  File "C:\Users\annek\AppData\Roaming\Python\Python312\site-packages\tensorflow\python\training\saver.py", line 1433, in restore
    names_to_keys = object_graph_key_mapping(save_path)
                    ^^^^^^^^^^^^^^^^^^^^^^^^^^^^^^^^^^^
  File "C:\Users\annek\AppData\Roaming\Python\Python312\site-packages\tensorflow\python\training\saver.py", line 1755, in object_graph_key_mapping
    object_graph_string = reader.get_tensor(trackable.OBJECT_GRAPH_PROTO_KEY)
                          ^^^^^^^^^^^^^^^^^^^^^^^^^^^^^^^^^^^^^^^^^^^^^^^^^^^
  File "C:\Users\annek\AppData\Roaming\Python\Python312\site-packages\tensorflow\python\training\py_checkpoint_reader.py", line 71, in get_tensor
    error_translator(e)
  File "C:\Users\annek\AppData\Roaming\Python\Python312\site-packages\tensorflow\python\training\py_checkpoint_reader.py", line 31, in error_translator
    raise errors_impl.NotFoundError(None, None, error_message)
tensorflow.python.framework.errors_impl.NotFoundError: Key _CHECKPOINTABLE_OBJECT_GRAPH not found in checkpoint

During handling of the above exception, another exception occurred:

Traceback (most recent call last):
  File "c:\Github\Thesis-Project\timegan\main.py", line 311, in main
    loaded_timegan.load_model(model_save_dir)
  File "c:\Github\Thesis-Project\timegan\main.py", line 226, in load_model
    saver.restore(self.session, os.path.join(save_dir, 'timegan_model'))
  File "C:\Users\annek\AppData\Roaming\Python\Python312\site-packages\tensorflow\python\training\saver.py", line 1438, in restore
    raise _wrap_restore_error_with_msg(
tensorflow.python.framework.errors_impl.NotFoundError: Restoring from checkpoint failed. This is most likely due to a Variable name or other graph key that is missing from the checkpoint. Please ensure that you have not altered the graph expected based on the checkpoint. Original error:

Graph execution error:

Detected at node 'save/RestoreV2' defined at (most recent call last):
    File "c:\Github\Thesis-Project\timegan\main.py", line 338, in <module>
    File "c:\Github\Thesis-Project\timegan\main.py", line 311, in main
    File "c:\Github\Thesis-Project\timegan\main.py", line 224, in load_model
Node: 'save/RestoreV2'
Key embedder/rnn_2/stacked_rnn_cells_2/gru_cell_6/bias not found in checkpoint
	 [[{{node save/RestoreV2}}]]

Original stack trace for 'save/RestoreV2':
  File "c:\Github\Thesis-Project\timegan\main.py", line 338, in <module>
  File "c:\Github\Thesis-Project\timegan\main.py", line 311, in main
  File "c:\Github\Thesis-Project\timegan\main.py", line 224, in load_model
  File "C:\Users\annek\AppData\Roaming\Python\Python312\site-packages\tensorflow\python\training\saver.py", line 934, in __init__
  File "C:\Users\annek\AppData\Roaming\Python\Python312\site-packages\tensorflow\python\training\saver.py", line 946, in build
  File "C:\Users\annek\AppData\Roaming\Python\Python312\site-packages\tensorflow\python\training\saver.py", line 974, in _build
  File "C:\Users\annek\AppData\Roaming\Python\Python312\site-packages\tensorflow\python\training\saver.py", line 543, in _build_internal
  File "C:\Users\annek\AppData\Roaming\Python\Python312\site-packages\tensorflow\python\training\saver.py", line 360, in _AddRestoreOps
  File "C:\Users\annek\AppData\Roaming\Python\Python312\site-packages\tensorflow\python\training\saver.py", line 611, in bulk_restore
  File "C:\Users\annek\AppData\Roaming\Python\Python312\site-packages\tensorflow\python\ops\gen_io_ops.py", line 1610, in restore_v2
  File "C:\Users\annek\AppData\Roaming\Python\Python312\site-packages\tensorflow\python\framework\op_def_library.py", line 796, in _apply_op_helper
  File "C:\Users\annek\AppData\Roaming\Python\Python312\site-packages\tensorflow\python\framework\ops.py", line 2682, in _create_op_internal
  File "C:\Users\annek\AppData\Roaming\Python\Python312\site-packages\tensorflow\python\framework\ops.py", line 1177, in from_node_def

2024-11-21 18:10:24,799 - WARNING - From c:\Github\Thesis-Project\timegan\main.py:126: The name tf.reset_default_graph is deprecated. Please use tf.compat.v1.reset_default_graph instead.

2024-11-21 18:10:26,283 - WARNING - From c:\Github\Thesis-Project\timegan\main.py:111: The name tf.train.AdamOptimizer is deprecated. Please use tf.compat.v1.train.AdamOptimizer instead.

2024-11-21 18:11:36,337 - INFO - Restoring parameters from ./timegan/saved_model\timegan_model
2024-11-21 18:11:37,292 - ERROR - An error occurred: Restoring from checkpoint failed. This is most likely due to a Variable name or other graph key that is missing from the checkpoint. Please ensure that you have not altered the graph expected based on the checkpoint. Original error:

Graph execution error:

Detected at node 'save/RestoreV2' defined at (most recent call last):
    File "c:\Github\Thesis-Project\timegan\main.py", line 338, in <module>
    File "c:\Github\Thesis-Project\timegan\main.py", line 311, in main
    File "c:\Github\Thesis-Project\timegan\main.py", line 224, in load_model
Node: 'save/RestoreV2'
Key embedder/rnn_2/stacked_rnn_cells_2/gru_cell_6/bias not found in checkpoint
	 [[{{node save/RestoreV2}}]]

Original stack trace for 'save/RestoreV2':
  File "c:\Github\Thesis-Project\timegan\main.py", line 338, in <module>
  File "c:\Github\Thesis-Project\timegan\main.py", line 311, in main
  File "c:\Github\Thesis-Project\timegan\main.py", line 224, in load_model
  File "C:\Users\annek\AppData\Roaming\Python\Python312\site-packages\tensorflow\python\training\saver.py", line 934, in __init__
  File "C:\Users\annek\AppData\Roaming\Python\Python312\site-packages\tensorflow\python\training\saver.py", line 946, in build
  File "C:\Users\annek\AppData\Roaming\Python\Python312\site-packages\tensorflow\python\training\saver.py", line 974, in _build
  File "C:\Users\annek\AppData\Roaming\Python\Python312\site-packages\tensorflow\python\training\saver.py", line 543, in _build_internal
  File "C:\Users\annek\AppData\Roaming\Python\Python312\site-packages\tensorflow\python\training\saver.py", line 360, in _AddRestoreOps
  File "C:\Users\annek\AppData\Roaming\Python\Python312\site-packages\tensorflow\python\training\saver.py", line 611, in bulk_restore
  File "C:\Users\annek\AppData\Roaming\Python\Python312\site-packages\tensorflow\python\ops\gen_io_ops.py", line 1610, in restore_v2
  File "C:\Users\annek\AppData\Roaming\Python\Python312\site-packages\tensorflow\python\framework\op_def_library.py", line 796, in _apply_op_helper
  File "C:\Users\annek\AppData\Roaming\Python\Python312\site-packages\tensorflow\python\framework\ops.py", line 2682, in _create_op_internal
  File "C:\Users\annek\AppData\Roaming\Python\Python312\site-packages\tensorflow\python\framework\ops.py", line 1177, in from_node_def
Traceback (most recent call last):
  File "C:\Users\annek\AppData\Roaming\Python\Python312\site-packages\tensorflow\python\client\session.py", line 1401, in _do_call
    return fn(*args)
           ^^^^^^^^^
  File "C:\Users\annek\AppData\Roaming\Python\Python312\site-packages\tensorflow\python\client\session.py", line 1384, in _run_fn
    return self._call_tf_sessionrun(options, feed_dict, fetch_list,
           ^^^^^^^^^^^^^^^^^^^^^^^^^^^^^^^^^^^^^^^^^^^^^^^^^^^^^^^^
  File "C:\Users\annek\AppData\Roaming\Python\Python312\site-packages\tensorflow\python\client\session.py", line 1477, in _call_tf_sessionrun
    return tf_session.TF_SessionRun_wrapper(self._session, options, feed_dict,
           ^^^^^^^^^^^^^^^^^^^^^^^^^^^^^^^^^^^^^^^^^^^^^^^^^^^^^^^^^^^^^^^^^^^
tensorflow.python.framework.errors_impl.NotFoundError: Key embedder/rnn_2/stacked_rnn_cells_2/gru_cell_6/bias not found in checkpoint
	 [[{{node save/RestoreV2}}]]

During handling of the above exception, another exception occurred:

Traceback (most recent call last):
  File "C:\Users\annek\AppData\Roaming\Python\Python312\site-packages\tensorflow\python\training\saver.py", line 1422, in restore
    sess.run(self.saver_def.restore_op_name,
  File "C:\Users\annek\AppData\Roaming\Python\Python312\site-packages\tensorflow\python\client\session.py", line 971, in run
    result = self._run(None, fetches, feed_dict, options_ptr,
             ^^^^^^^^^^^^^^^^^^^^^^^^^^^^^^^^^^^^^^^^^^^^^^^^
  File "C:\Users\annek\AppData\Roaming\Python\Python312\site-packages\tensorflow\python\client\session.py", line 1214, in _run
    results = self._do_run(handle, final_targets, final_fetches,
              ^^^^^^^^^^^^^^^^^^^^^^^^^^^^^^^^^^^^^^^^^^^^^^^^^^
  File "C:\Users\annek\AppData\Roaming\Python\Python312\site-packages\tensorflow\python\client\session.py", line 1394, in _do_run
    return self._do_call(_run_fn, feeds, fetches, targets, options,
           ^^^^^^^^^^^^^^^^^^^^^^^^^^^^^^^^^^^^^^^^^^^^^^^^^^^^^^^^
  File "C:\Users\annek\AppData\Roaming\Python\Python312\site-packages\tensorflow\python\client\session.py", line 1420, in _do_call
    raise type(e)(node_def, op, message)  # pylint: disable=no-value-for-parameter
    ^^^^^^^^^^^^^^^^^^^^^^^^^^^^^^^^^^^^
tensorflow.python.framework.errors_impl.NotFoundError: Graph execution error:

Detected at node 'save/RestoreV2' defined at (most recent call last):
    File "c:\Github\Thesis-Project\timegan\main.py", line 338, in <module>
    File "c:\Github\Thesis-Project\timegan\main.py", line 311, in main
    File "c:\Github\Thesis-Project\timegan\main.py", line 224, in load_model
Node: 'save/RestoreV2'
Key embedder/rnn_2/stacked_rnn_cells_2/gru_cell_6/bias not found in checkpoint
	 [[{{node save/RestoreV2}}]]

Original stack trace for 'save/RestoreV2':
  File "c:\Github\Thesis-Project\timegan\main.py", line 338, in <module>
  File "c:\Github\Thesis-Project\timegan\main.py", line 311, in main
  File "c:\Github\Thesis-Project\timegan\main.py", line 224, in load_model
  File "C:\Users\annek\AppData\Roaming\Python\Python312\site-packages\tensorflow\python\training\saver.py", line 934, in __init__
  File "C:\Users\annek\AppData\Roaming\Python\Python312\site-packages\tensorflow\python\training\saver.py", line 946, in build
  File "C:\Users\annek\AppData\Roaming\Python\Python312\site-packages\tensorflow\python\training\saver.py", line 974, in _build
  File "C:\Users\annek\AppData\Roaming\Python\Python312\site-packages\tensorflow\python\training\saver.py", line 543, in _build_internal
  File "C:\Users\annek\AppData\Roaming\Python\Python312\site-packages\tensorflow\python\training\saver.py", line 360, in _AddRestoreOps
  File "C:\Users\annek\AppData\Roaming\Python\Python312\site-packages\tensorflow\python\training\saver.py", line 611, in bulk_restore
  File "C:\Users\annek\AppData\Roaming\Python\Python312\site-packages\tensorflow\python\ops\gen_io_ops.py", line 1610, in restore_v2
  File "C:\Users\annek\AppData\Roaming\Python\Python312\site-packages\tensorflow\python\framework\op_def_library.py", line 796, in _apply_op_helper
  File "C:\Users\annek\AppData\Roaming\Python\Python312\site-packages\tensorflow\python\framework\ops.py", line 2682, in _create_op_internal
  File "C:\Users\annek\AppData\Roaming\Python\Python312\site-packages\tensorflow\python\framework\ops.py", line 1177, in from_node_def


During handling of the above exception, another exception occurred:

Traceback (most recent call last):
  File "C:\Users\annek\AppData\Roaming\Python\Python312\site-packages\tensorflow\python\training\py_checkpoint_reader.py", line 66, in get_tensor
    return CheckpointReader.CheckpointReader_GetTensor(
           ^^^^^^^^^^^^^^^^^^^^^^^^^^^^^^^^^^^^^^^^^^^^
RuntimeError: Key _CHECKPOINTABLE_OBJECT_GRAPH not found in checkpoint

During handling of the above exception, another exception occurred:

Traceback (most recent call last):
  File "C:\Users\annek\AppData\Roaming\Python\Python312\site-packages\tensorflow\python\training\saver.py", line 1433, in restore
    names_to_keys = object_graph_key_mapping(save_path)
                    ^^^^^^^^^^^^^^^^^^^^^^^^^^^^^^^^^^^
  File "C:\Users\annek\AppData\Roaming\Python\Python312\site-packages\tensorflow\python\training\saver.py", line 1755, in object_graph_key_mapping
    object_graph_string = reader.get_tensor(trackable.OBJECT_GRAPH_PROTO_KEY)
                          ^^^^^^^^^^^^^^^^^^^^^^^^^^^^^^^^^^^^^^^^^^^^^^^^^^^
  File "C:\Users\annek\AppData\Roaming\Python\Python312\site-packages\tensorflow\python\training\py_checkpoint_reader.py", line 71, in get_tensor
    error_translator(e)
  File "C:\Users\annek\AppData\Roaming\Python\Python312\site-packages\tensorflow\python\training\py_checkpoint_reader.py", line 31, in error_translator
    raise errors_impl.NotFoundError(None, None, error_message)
tensorflow.python.framework.errors_impl.NotFoundError: Key _CHECKPOINTABLE_OBJECT_GRAPH not found in checkpoint

During handling of the above exception, another exception occurred:

Traceback (most recent call last):
  File "c:\Github\Thesis-Project\timegan\main.py", line 311, in main
    loaded_timegan.load_model(model_save_dir)
  File "c:\Github\Thesis-Project\timegan\main.py", line 226, in load_model
    saver.restore(self.session, os.path.join(save_dir, 'timegan_model'))
  File "C:\Users\annek\AppData\Roaming\Python\Python312\site-packages\tensorflow\python\training\saver.py", line 1438, in restore
    raise _wrap_restore_error_with_msg(
tensorflow.python.framework.errors_impl.NotFoundError: Restoring from checkpoint failed. This is most likely due to a Variable name or other graph key that is missing from the checkpoint. Please ensure that you have not altered the graph expected based on the checkpoint. Original error:

Graph execution error:

Detected at node 'save/RestoreV2' defined at (most recent call last):
    File "c:\Github\Thesis-Project\timegan\main.py", line 338, in <module>
    File "c:\Github\Thesis-Project\timegan\main.py", line 311, in main
    File "c:\Github\Thesis-Project\timegan\main.py", line 224, in load_model
Node: 'save/RestoreV2'
Key embedder/rnn_2/stacked_rnn_cells_2/gru_cell_6/bias not found in checkpoint
	 [[{{node save/RestoreV2}}]]

Original stack trace for 'save/RestoreV2':
  File "c:\Github\Thesis-Project\timegan\main.py", line 338, in <module>
  File "c:\Github\Thesis-Project\timegan\main.py", line 311, in main
  File "c:\Github\Thesis-Project\timegan\main.py", line 224, in load_model
  File "C:\Users\annek\AppData\Roaming\Python\Python312\site-packages\tensorflow\python\training\saver.py", line 934, in __init__
  File "C:\Users\annek\AppData\Roaming\Python\Python312\site-packages\tensorflow\python\training\saver.py", line 946, in build
  File "C:\Users\annek\AppData\Roaming\Python\Python312\site-packages\tensorflow\python\training\saver.py", line 974, in _build
  File "C:\Users\annek\AppData\Roaming\Python\Python312\site-packages\tensorflow\python\training\saver.py", line 543, in _build_internal
  File "C:\Users\annek\AppData\Roaming\Python\Python312\site-packages\tensorflow\python\training\saver.py", line 360, in _AddRestoreOps
  File "C:\Users\annek\AppData\Roaming\Python\Python312\site-packages\tensorflow\python\training\saver.py", line 611, in bulk_restore
  File "C:\Users\annek\AppData\Roaming\Python\Python312\site-packages\tensorflow\python\ops\gen_io_ops.py", line 1610, in restore_v2
  File "C:\Users\annek\AppData\Roaming\Python\Python312\site-packages\tensorflow\python\framework\op_def_library.py", line 796, in _apply_op_helper
  File "C:\Users\annek\AppData\Roaming\Python\Python312\site-packages\tensorflow\python\framework\ops.py", line 2682, in _create_op_internal
  File "C:\Users\annek\AppData\Roaming\Python\Python312\site-packages\tensorflow\python\framework\ops.py", line 1177, in from_node_def

2024-11-21 18:16:14,111 - WARNING - 5 out of the last 5 calls to <function TensorFlowTrainer.make_train_function.<locals>.one_step_on_iterator at 0x00000223102CAF20> triggered tf.function retracing. Tracing is expensive and the excessive number of tracings could be due to (1) creating @tf.function repeatedly in a loop, (2) passing tensors with different shapes, (3) passing Python objects instead of tensors. For (1), please define your @tf.function outside of the loop. For (2), @tf.function has reduce_retracing=True option that can avoid unnecessary retracing. For (3), please refer to https://www.tensorflow.org/guide/function#controlling_retracing and https://www.tensorflow.org/api_docs/python/tf/function for  more details.
2024-11-21 18:16:26,372 - WARNING - 6 out of the last 6 calls to <function TensorFlowTrainer.make_train_function.<locals>.one_step_on_iterator at 0x00000223102CAF20> triggered tf.function retracing. Tracing is expensive and the excessive number of tracings could be due to (1) creating @tf.function repeatedly in a loop, (2) passing tensors with different shapes, (3) passing Python objects instead of tensors. For (1), please define your @tf.function outside of the loop. For (2), @tf.function has reduce_retracing=True option that can avoid unnecessary retracing. For (3), please refer to https://www.tensorflow.org/guide/function#controlling_retracing and https://www.tensorflow.org/api_docs/python/tf/function for  more details.
2024-11-21 18:17:19,285 - ERROR - An error occurred: Invalid filepath extension for saving. Please add either a `.keras` extension for the native Keras format (recommended) or a `.h5` extension. Use `model.export(filepath)` if you want to export a SavedModel for use with TFLite/TFServing/etc. Received: filepath=./timegan/saved_model\timegan_model.
Traceback (most recent call last):
  File "c:\Github\Thesis-Project\timegan\main.py", line 209, in main
    timegan.save_model(model_save_dir)
  File "c:\Github\Thesis-Project\timegan\main.py", line 114, in save_model
    self.model.save(os.path.join(save_dir, 'timegan_model'))
  File "C:\Users\annek\AppData\Roaming\Python\Python312\site-packages\keras\src\utils\traceback_utils.py", line 122, in error_handler
    raise e.with_traceback(filtered_tb) from None
  File "C:\Users\annek\AppData\Roaming\Python\Python312\site-packages\keras\src\saving\saving_api.py", line 114, in save_model
    raise ValueError(
ValueError: Invalid filepath extension for saving. Please add either a `.keras` extension for the native Keras format (recommended) or a `.h5` extension. Use `model.export(filepath)` if you want to export a SavedModel for use with TFLite/TFServing/etc. Received: filepath=./timegan/saved_model\timegan_model.
2024-11-21 18:19:30,481 - ERROR - An error occurred: in user code:

    File "c:\Github\Thesis-Project\timegan\main.py", line 48, in train_step  *
        loss = tf.keras.losses.mean_squared_error(X, X_tilde)

    AttributeError: module 'keras._tf_keras.keras.losses' has no attribute 'mean_squared_error'
Traceback (most recent call last):
  File "c:\Github\Thesis-Project\timegan\main.py", line 220, in main
    timegan.train(train_data)
  File "c:\Github\Thesis-Project\timegan\main.py", line 113, in train
    loss = self.train_step(ori_data, Z_mb)
           ^^^^^^^^^^^^^^^^^^^^^^^^^^^^^^^
  File "C:\Users\annek\AppData\Roaming\Python\Python312\site-packages\tensorflow\python\util\traceback_utils.py", line 153, in error_handler
    raise e.with_traceback(filtered_tb) from None
  File "C:\Users\annek\AppData\Local\Temp\__autograph_generated_filerqcndduz.py", line 13, in tf__train_step
    loss = ag__.converted_call(ag__.ld(tf).keras.losses.mean_squared_error, (ag__.ld(X), ag__.ld(X_tilde)), None, fscope)
                               ^^^^^^^^^^^^^^^^^^^^^^^^^^^^^^^^^^^^^^^^^^^
AttributeError: in user code:

    File "c:\Github\Thesis-Project\timegan\main.py", line 48, in train_step  *
        loss = tf.keras.losses.mean_squared_error(X, X_tilde)

    AttributeError: module 'keras._tf_keras.keras.losses' has no attribute 'mean_squared_error'

2024-11-21 18:23:05,413 - ERROR - An error occurred: in user code:

    File "c:\Github\Thesis-Project\timegan\main.py", line 49, in train_step  *
        loss = tf.reduce_mean(tf.square(X - X_tilde))

    TypeError: Input 'y' of 'Sub' Op has type float32 that does not match type float64 of argument 'x'.
Traceback (most recent call last):
  File "c:\Github\Thesis-Project\timegan\main.py", line 222, in main
    timegan.train(train_data)
  File "c:\Github\Thesis-Project\timegan\main.py", line 115, in train
    loss = self.train_step(ori_data, Z_mb)
           ^^^^^^^^^^^^^^^^^^^^^^^^^^^^^^^
  File "C:\Users\annek\AppData\Roaming\Python\Python312\site-packages\tensorflow\python\util\traceback_utils.py", line 153, in error_handler
    raise e.with_traceback(filtered_tb) from None
  File "C:\Users\annek\AppData\Local\Temp\__autograph_generated_filex1z1rp9f.py", line 13, in tf__train_step
    loss = ag__.converted_call(ag__.ld(tf).reduce_mean, (ag__.converted_call(ag__.ld(tf).square, (ag__.ld(X) - ag__.ld(X_tilde),), None, fscope),), None, fscope)
                                                                                                  ~~~~~~~~~~~^~~~~~~~~~~~~~~~~~
TypeError: in user code:

    File "c:\Github\Thesis-Project\timegan\main.py", line 49, in train_step  *
        loss = tf.reduce_mean(tf.square(X - X_tilde))

    TypeError: Input 'y' of 'Sub' Op has type float32 that does not match type float64 of argument 'x'.

2024-11-21 23:35:49,043 - WARNING - 5 out of the last 5 calls to <function TensorFlowTrainer.make_train_function.<locals>.one_step_on_iterator at 0x0000016BF7A3C180> triggered tf.function retracing. Tracing is expensive and the excessive number of tracings could be due to (1) creating @tf.function repeatedly in a loop, (2) passing tensors with different shapes, (3) passing Python objects instead of tensors. For (1), please define your @tf.function outside of the loop. For (2), @tf.function has reduce_retracing=True option that can avoid unnecessary retracing. For (3), please refer to https://www.tensorflow.org/guide/function#controlling_retracing and https://www.tensorflow.org/api_docs/python/tf/function for  more details.
2024-11-21 23:36:03,780 - WARNING - 6 out of the last 6 calls to <function TensorFlowTrainer.make_train_function.<locals>.one_step_on_iterator at 0x0000016BF7A3C180> triggered tf.function retracing. Tracing is expensive and the excessive number of tracings could be due to (1) creating @tf.function repeatedly in a loop, (2) passing tensors with different shapes, (3) passing Python objects instead of tensors. For (1), please define your @tf.function outside of the loop. For (2), @tf.function has reduce_retracing=True option that can avoid unnecessary retracing. For (3), please refer to https://www.tensorflow.org/guide/function#controlling_retracing and https://www.tensorflow.org/api_docs/python/tf/function for  more details.
2024-11-21 23:37:03,764 - ERROR - An error occurred: Could not locate class 'method'. Make sure custom classes are decorated with `@keras.saving.register_keras_serializable()`. Full object config: {'module': 'builtins', 'class_name': 'method', 'config': '_combined_loss', 'registered_name': 'method'}
Traceback (most recent call last):
  File "c:\Github\Thesis-Project\timegan\main copy.py", line 311, in main
    loaded_timegan.load_model(model_save_dir)
  File "c:\Github\Thesis-Project\timegan\main copy.py", line 221, in load_model
    self.model = tf.keras.models.load_model(model_path)
                 ^^^^^^^^^^^^^^^^^^^^^^^^^^^^^^^^^^^^^^
  File "C:\Users\annek\AppData\Roaming\Python\Python312\site-packages\keras\src\saving\saving_api.py", line 187, in load_model
    return saving_lib.load_model(
           ^^^^^^^^^^^^^^^^^^^^^^
  File "C:\Users\annek\AppData\Roaming\Python\Python312\site-packages\keras\src\saving\saving_lib.py", line 365, in load_model
    return _load_model_from_fileobj(
           ^^^^^^^^^^^^^^^^^^^^^^^^^
  File "C:\Users\annek\AppData\Roaming\Python\Python312\site-packages\keras\src\saving\saving_lib.py", line 442, in _load_model_from_fileobj
    model = _model_from_config(
            ^^^^^^^^^^^^^^^^^^^
  File "C:\Users\annek\AppData\Roaming\Python\Python312\site-packages\keras\src\saving\saving_lib.py", line 431, in _model_from_config
    model = deserialize_keras_object(
            ^^^^^^^^^^^^^^^^^^^^^^^^^
  File "C:\Users\annek\AppData\Roaming\Python\Python312\site-packages\keras\src\saving\serialization_lib.py", line 734, in deserialize_keras_object
    instance.compile_from_config(compile_config)
  File "C:\Users\annek\AppData\Roaming\Python\Python312\site-packages\keras\src\trainers\trainer.py", line 910, in compile_from_config
    config = serialization_lib.deserialize_keras_object(config)
             ^^^^^^^^^^^^^^^^^^^^^^^^^^^^^^^^^^^^^^^^^^^^^^^^^^
  File "C:\Users\annek\AppData\Roaming\Python\Python312\site-packages\keras\src\saving\serialization_lib.py", line 595, in deserialize_keras_object
    key: deserialize_keras_object(
         ^^^^^^^^^^^^^^^^^^^^^^^^^
  File "C:\Users\annek\AppData\Roaming\Python\Python312\site-packages\keras\src\saving\serialization_lib.py", line 694, in deserialize_keras_object
    cls = _retrieve_class_or_fn(
          ^^^^^^^^^^^^^^^^^^^^^^
  File "C:\Users\annek\AppData\Roaming\Python\Python312\site-packages\keras\src\saving\serialization_lib.py", line 812, in _retrieve_class_or_fn
    raise TypeError(
TypeError: Could not locate class 'method'. Make sure custom classes are decorated with `@keras.saving.register_keras_serializable()`. Full object config: {'module': 'builtins', 'class_name': 'method', 'config': '_combined_loss', 'registered_name': 'method'}
2024-11-21 23:48:56,132 - ERROR - An error occurred: The following argument(s) are not supported: ['custom_objects']
Traceback (most recent call last):
  File "c:\Github\Thesis-Project\timegan\main copy.py", line 269, in main
    timegan.save_model(model_save_dir)
  File "c:\Github\Thesis-Project\timegan\main copy.py", line 178, in save_model
    self.model.save(model_path, custom_objects={'combined_loss': combined_loss})
  File "C:\Users\annek\AppData\Roaming\Python\Python312\site-packages\keras\src\utils\traceback_utils.py", line 122, in error_handler
    raise e.with_traceback(filtered_tb) from None
  File "C:\Users\annek\AppData\Roaming\Python\Python312\site-packages\keras\src\saving\saving_api.py", line 76, in save_model
    raise ValueError(
ValueError: The following argument(s) are not supported: ['custom_objects']
2024-11-22 11:28:40,225 - ERROR - An error occurred: The following argument(s) are not supported: ['custom_objects']
Traceback (most recent call last):
  File "c:\Github\Thesis-Project\timegan\main copy.py", line 269, in main
    timegan.save_model(model_save_dir)
  File "c:\Github\Thesis-Project\timegan\main copy.py", line 178, in save_model
    self.model.save(model_path, custom_objects={'combined_loss': combined_loss})
  File "C:\Users\annek\AppData\Roaming\Python\Python312\site-packages\keras\src\utils\traceback_utils.py", line 122, in error_handler
    raise e.with_traceback(filtered_tb) from None
  File "C:\Users\annek\AppData\Roaming\Python\Python312\site-packages\keras\src\saving\saving_api.py", line 76, in save_model
    raise ValueError(
ValueError: The following argument(s) are not supported: ['custom_objects']
2024-11-22 11:33:54,461 - ERROR - An error occurred: this __dict__ descriptor does not support '_DictWrapper' objects
Traceback (most recent call last):
  File "c:\Github\Thesis-Project\timegan\main copy.py", line 232, in main
    timegan.save_model(model_save_dir)
  File "c:\Github\Thesis-Project\timegan\main copy.py", line 156, in save_model
    tf.saved_model.save(self.model, os.path.join(save_dir, 'timegan_model'))
  File "C:\Users\annek\AppData\Roaming\Python\Python312\site-packages\tensorflow\python\saved_model\save.py", line 1432, in save
    save_and_return_nodes(obj, export_dir, signatures, options)
  File "C:\Users\annek\AppData\Roaming\Python\Python312\site-packages\tensorflow\python\saved_model\save.py", line 1467, in save_and_return_nodes
    _build_meta_graph(obj, signatures, options, meta_graph_def))
    ^^^^^^^^^^^^^^^^^^^^^^^^^^^^^^^^^^^^^^^^^^^^^^^^^^^^^^^^^^^
  File "C:\Users\annek\AppData\Roaming\Python\Python312\site-packages\tensorflow\python\saved_model\save.py", line 1682, in _build_meta_graph
    return _build_meta_graph_impl(obj, signatures, options, meta_graph_def)
           ^^^^^^^^^^^^^^^^^^^^^^^^^^^^^^^^^^^^^^^^^^^^^^^^^^^^^^^^^^^^^^^^
  File "C:\Users\annek\AppData\Roaming\Python\Python312\site-packages\tensorflow\python\saved_model\save.py", line 1604, in _build_meta_graph_impl
    saveable_view = _SaveableView(augmented_graph_view, options)
                    ^^^^^^^^^^^^^^^^^^^^^^^^^^^^^^^^^^^^^^^^^^^^
  File "C:\Users\annek\AppData\Roaming\Python\Python312\site-packages\tensorflow\python\saved_model\save.py", line 285, in __init__
    checkpoint_util.objects_ids_and_slot_variables_and_paths(
  File "C:\Users\annek\AppData\Roaming\Python\Python312\site-packages\tensorflow\python\checkpoint\util.py", line 160, in objects_ids_and_slot_variables_and_paths
    trackable_objects, node_paths = graph_view.breadth_first_traversal()
                                    ^^^^^^^^^^^^^^^^^^^^^^^^^^^^^^^^^^^^
  File "C:\Users\annek\AppData\Roaming\Python\Python312\site-packages\tensorflow\python\checkpoint\graph_view.py", line 124, in breadth_first_traversal
    return self._breadth_first_traversal()
           ^^^^^^^^^^^^^^^^^^^^^^^^^^^^^^^
  File "C:\Users\annek\AppData\Roaming\Python\Python312\site-packages\tensorflow\python\saved_model\save.py", line 156, in _breadth_first_traversal
    super(_AugmentedGraphView, self)._breadth_first_traversal())
    ^^^^^^^^^^^^^^^^^^^^^^^^^^^^^^^^^^^^^^^^^^^^^^^^^^^^^^^^^^^
  File "C:\Users\annek\AppData\Roaming\Python\Python312\site-packages\tensorflow\python\checkpoint\graph_view.py", line 128, in _breadth_first_traversal
    return super(ObjectGraphView, self)._descendants_with_paths()
           ^^^^^^^^^^^^^^^^^^^^^^^^^^^^^^^^^^^^^^^^^^^^^^^^^^^^^^
  File "C:\Users\annek\AppData\Roaming\Python\Python312\site-packages\tensorflow\python\checkpoint\trackable_view.py", line 111, in _descendants_with_paths
    for name, dependency in self.children(current_trackable).items():
                            ^^^^^^^^^^^^^^^^^^^^^^^^^^^^^^^^
  File "C:\Users\annek\AppData\Roaming\Python\Python312\site-packages\tensorflow\python\checkpoint\graph_view.py", line 97, in children
    for name, ref in self.list_children(obj, **kwargs):
                     ^^^^^^^^^^^^^^^^^^^^^^^^^^^^^^^^^
  File "C:\Users\annek\AppData\Roaming\Python\Python312\site-packages\tensorflow\python\saved_model\save.py", line 190, in list_children
    for name, child in super(_AugmentedGraphView, self).list_children(
                       ^^^^^^^^^^^^^^^^^^^^^^^^^^^^^^^^^^^^^^^^^^^^^^^
  File "C:\Users\annek\AppData\Roaming\Python\Python312\site-packages\tensorflow\python\checkpoint\graph_view.py", line 75, in list_children
    for name, ref in super(ObjectGraphView,
                     ^^^^^^^^^^^^^^^^^^^^^^
  File "C:\Users\annek\AppData\Roaming\Python\Python312\site-packages\tensorflow\python\checkpoint\trackable_view.py", line 85, in children
    ref = converter.convert_to_trackable(ref, parent=obj)
          ^^^^^^^^^^^^^^^^^^^^^^^^^^^^^^^^^^^^^^^^^^^^^^^
  File "C:\Users\annek\AppData\Roaming\Python\Python312\site-packages\tensorflow\python\trackable\converter.py", line 31, in convert_to_trackable
    if (tensor_util.is_tf_type(obj) and
        ^^^^^^^^^^^^^^^^^^^^^^^^^^^
  File "C:\Users\annek\AppData\Roaming\Python\Python312\site-packages\tensorflow\python\framework\tensor_util.py", line 1156, in is_tf_type
    return isinstance(x, tf_type_classes)
           ^^^^^^^^^^^^^^^^^^^^^^^^^^^^^^
  File "C:\Program Files\Python312\Lib\typing.py", line 1921, in __instancecheck__
    val = getattr_static(instance, attr)
          ^^^^^^^^^^^^^^^^^^^^^^^^^^^^^^
  File "C:\Program Files\Python312\Lib\inspect.py", line 1860, in getattr_static
    instance_result = _check_instance(obj, attr)
                      ^^^^^^^^^^^^^^^^^^^^^^^^^^
  File "C:\Program Files\Python312\Lib\inspect.py", line 1796, in _check_instance
    instance_dict = object.__getattribute__(obj, "__dict__")
                    ^^^^^^^^^^^^^^^^^^^^^^^^^^^^^^^^^^^^^^^^
TypeError: this __dict__ descriptor does not support '_DictWrapper' objects
2024-11-22 11:36:19,993 - ERROR - An error occurred: The filename must end in `.weights.h5`. Received: filepath=./timegan/saved_model\model_weights.h5
Traceback (most recent call last):
  File "c:\Github\Thesis-Project\timegan\main copy.py", line 255, in main
    timegan.save_model(model_save_dir)
  File "c:\Github\Thesis-Project\timegan\main copy.py", line 161, in save_model
    self.model.save_weights(os.path.join(save_dir, 'model_weights.h5'))
  File "C:\Users\annek\AppData\Roaming\Python\Python312\site-packages\keras\src\utils\traceback_utils.py", line 122, in error_handler
    raise e.with_traceback(filtered_tb) from None
  File "C:\Users\annek\AppData\Roaming\Python\Python312\site-packages\keras\src\saving\saving_api.py", line 222, in save_weights
    raise ValueError(
ValueError: The filename must end in `.weights.h5`. Received: filepath=./timegan/saved_model\model_weights.h5
2024-11-22 11:39:46,981 - ERROR - An error occurred: The filename must end in `.weights.h5`. Received: filepath=./timegan/saved_model\embedder_weights.h5
Traceback (most recent call last):
  File "c:\Github\Thesis-Project\timegan\main copy.py", line 255, in main
    timegan.save_model(model_save_dir)
  File "c:\Github\Thesis-Project\timegan\main copy.py", line 168, in save_model
    self.embedder.save_weights(os.path.join(save_dir, 'embedder_weights.h5'))
  File "C:\Users\annek\AppData\Roaming\Python\Python312\site-packages\keras\src\utils\traceback_utils.py", line 122, in error_handler
    raise e.with_traceback(filtered_tb) from None
  File "C:\Users\annek\AppData\Roaming\Python\Python312\site-packages\keras\src\saving\saving_api.py", line 222, in save_weights
    raise ValueError(
ValueError: The filename must end in `.weights.h5`. Received: filepath=./timegan/saved_model\embedder_weights.h5
2024-11-22 11:41:11,635 - ERROR - An error occurred: Could not locate function 'combined_loss'. Make sure custom classes are decorated with `@keras.saving.register_keras_serializable()`. Full object config: {'module': 'builtins', 'class_name': 'function', 'config': 'combined_loss', 'registered_name': 'function'}
Traceback (most recent call last):
  File "c:\Github\Thesis-Project\timegan\main copy.py", line 263, in main
    loaded_timegan.load_model(model_save_dir)
  File "c:\Github\Thesis-Project\timegan\main copy.py", line 184, in load_model
    self.model = tf.keras.models.model_from_json(model_json)
                 ^^^^^^^^^^^^^^^^^^^^^^^^^^^^^^^^^^^^^^^^^^^
  File "C:\Users\annek\AppData\Roaming\Python\Python312\site-packages\keras\src\models\model.py", line 583, in model_from_json
    return serialization_lib.deserialize_keras_object(
           ^^^^^^^^^^^^^^^^^^^^^^^^^^^^^^^^^^^^^^^^^^^
  File "C:\Users\annek\AppData\Roaming\Python\Python312\site-packages\keras\src\saving\serialization_lib.py", line 734, in deserialize_keras_object
    instance.compile_from_config(compile_config)
  File "C:\Users\annek\AppData\Roaming\Python\Python312\site-packages\keras\src\trainers\trainer.py", line 910, in compile_from_config
    config = serialization_lib.deserialize_keras_object(config)
             ^^^^^^^^^^^^^^^^^^^^^^^^^^^^^^^^^^^^^^^^^^^^^^^^^^
  File "C:\Users\annek\AppData\Roaming\Python\Python312\site-packages\keras\src\saving\serialization_lib.py", line 595, in deserialize_keras_object
    key: deserialize_keras_object(
         ^^^^^^^^^^^^^^^^^^^^^^^^^
  File "C:\Users\annek\AppData\Roaming\Python\Python312\site-packages\keras\src\saving\serialization_lib.py", line 678, in deserialize_keras_object
    return _retrieve_class_or_fn(
           ^^^^^^^^^^^^^^^^^^^^^^
  File "C:\Users\annek\AppData\Roaming\Python\Python312\site-packages\keras\src\saving\serialization_lib.py", line 812, in _retrieve_class_or_fn
    raise TypeError(
TypeError: Could not locate function 'combined_loss'. Make sure custom classes are decorated with `@keras.saving.register_keras_serializable()`. Full object config: {'module': 'builtins', 'class_name': 'function', 'config': 'combined_loss', 'registered_name': 'function'}
2024-11-22 12:03:53,598 - WARNING - 5 out of the last 5 calls to <function TensorFlowTrainer.make_train_function.<locals>.one_step_on_iterator at 0x000001BEE685E480> triggered tf.function retracing. Tracing is expensive and the excessive number of tracings could be due to (1) creating @tf.function repeatedly in a loop, (2) passing tensors with different shapes, (3) passing Python objects instead of tensors. For (1), please define your @tf.function outside of the loop. For (2), @tf.function has reduce_retracing=True option that can avoid unnecessary retracing. For (3), please refer to https://www.tensorflow.org/guide/function#controlling_retracing and https://www.tensorflow.org/api_docs/python/tf/function for  more details.
2024-11-22 12:04:02,475 - WARNING - 6 out of the last 6 calls to <function TensorFlowTrainer.make_train_function.<locals>.one_step_on_iterator at 0x000001BEE685E480> triggered tf.function retracing. Tracing is expensive and the excessive number of tracings could be due to (1) creating @tf.function repeatedly in a loop, (2) passing tensors with different shapes, (3) passing Python objects instead of tensors. For (1), please define your @tf.function outside of the loop. For (2), @tf.function has reduce_retracing=True option that can avoid unnecessary retracing. For (3), please refer to https://www.tensorflow.org/guide/function#controlling_retracing and https://www.tensorflow.org/api_docs/python/tf/function for  more details.
2024-11-22 13:26:16,689 - INFO - Starting parallel processing with 2 processes
2024-11-22 13:26:28,130 - INFO - Starting processing of file: collection1u00001s00001_hw00002.svc
2024-11-22 13:26:30,218 - WARNING - From c:\Github\Thesis-Project\timegan\timegan copy.py:19: The name tf.disable_eager_execution is deprecated. Please use tf.compat.v1.disable_eager_execution instead.

2024-11-22 13:26:34,322 - WARNING - From c:\Github\Thesis-Project\timegan\timegan copy.py:130: The name tf.train.AdamOptimizer is deprecated. Please use tf.compat.v1.train.AdamOptimizer instead.

2024-11-22 13:26:44,221 - INFO - Completed processing file collection1u00001s00001_hw00002.svc. Time taken: 16.09 seconds
2024-11-22 13:26:44,303 - INFO - 
Processing Summary:
2024-11-22 13:26:44,303 - INFO - Total files processed: 1
2024-11-22 13:26:44,305 - INFO - Successfully processed: 1
2024-11-22 13:26:44,305 - INFO - Failed to process: 0
2024-11-22 13:26:44,305 - INFO - Total wall time: 27.61 seconds
2024-11-22 13:26:44,305 - INFO - Total processing time: 16.09 seconds
2024-11-22 13:29:08,583 - INFO - Starting parallel processing with 2 processes
2024-11-22 13:29:19,976 - INFO - Starting processing of file: collection1u00001s00001_hw00002.svc
2024-11-22 13:29:21,556 - WARNING - From c:\Github\Thesis-Project\timegan\timegan copy.py:19: The name tf.disable_eager_execution is deprecated. Please use tf.compat.v1.disable_eager_execution instead.

2024-11-22 13:29:25,623 - WARNING - From c:\Github\Thesis-Project\timegan\timegan copy.py:130: The name tf.train.AdamOptimizer is deprecated. Please use tf.compat.v1.train.AdamOptimizer instead.

2024-11-22 13:29:58,945 - INFO - Completed processing file collection1u00001s00001_hw00002.svc. Time taken: 38.97 seconds
2024-11-22 13:29:59,032 - INFO - 
Processing Summary:
2024-11-22 13:29:59,044 - INFO - Total files processed: 1
2024-11-22 13:29:59,044 - INFO - Successfully processed: 1
2024-11-22 13:29:59,044 - INFO - Failed to process: 0
2024-11-22 13:29:59,044 - INFO - Total wall time: 50.45 seconds
2024-11-22 13:29:59,044 - INFO - Total processing time: 38.97 seconds
